/**
 * TASK-0005: リトライユーティリティ テストケース
 *
 * 【テストフェーズ】: TDD Red Phase（失敗するテストを作成）
 * 【作成日】: 2025-10-29
 * 【テストフレームワーク】: Vitest 2.1.4
 * 【言語】: TypeScript 5.x
 * 【目的】: リトライロジックのテスト実装（実装は存在しないため、全テストが失敗する）
 */

import { describe, it, expect, beforeEach, afterEach, vi } from 'vitest';
import {
  sleep,
  calculateBackoffDelay,
  retryableRequest,
} from '../../src/utils/retry';

// =========================================
// 正常系テストケース（3件）
// =========================================
describe('retry.ts - 正常系テストケース', () => {
  beforeEach(() => {
    // 【テスト前準備】: 各テスト実行前にモックをクリア
    vi.clearAllMocks();
  });

  afterEach(() => {
    // 【テスト後処理】: タイマーモックをリセット
    vi.useRealTimers();
  });

  /**
   * TC-NORMAL-011: sleep() - 指定時間待機🔵
   *
   * 【テスト目的】: 指定ミリ秒待機してPromiseがresolveされること
   * 【テスト内容】: 1000ms待機後にPromiseがresolve
   * 【期待される動作】: 指定時間経過後にresolve
   * 🔵 信頼性レベル: 青信号（要件定義書のsleep()仕様から抽出）
   */
  it('TC-NORMAL-011: sleep() - 指定時間待機', async () => {
    // Given（前提条件）: フェイクタイマーを使用
    // 【テストデータ準備】: 1秒待機
    vi.useFakeTimers();
    const ms = 1000;

    // When（実行）: sleep()を呼び出し
    // 【実際の処理実行】: Promise-based遅延関数の動作
    const sleepPromise = sleep(ms);

    // When: タイマーを進める
    await vi.advanceTimersByTimeAsync(ms);

    // Then（検証）: Promiseがresolveされる
    // 【結果検証】: 指定時間経過後にresolve
    await expect(sleepPromise).resolves.toBeUndefined();
    // 【確認内容】: setTimeoutによる遅延実装が正しく動作
  });

  /**
   * TC-NORMAL-012: calculateBackoffDelay() - Exponential backoff計算🔵
   *
   * 【テスト目的】: Exponential backoffの遅延時間が正しく計算されること
   * 【テスト内容】: attempt回数に応じた遅延時間の計算
   * 【期待される動作】: baseDelay * (2 ^ attempt) の計算式で遅延時間を算出
   * 🔵 信頼性レベル: 青信号（要件定義書の計算式から抽出）
   */
  it('TC-NORMAL-012: calculateBackoffDelay() - Exponential backoff計算', () => {
    // Given（前提条件）: baseDelayを準備
    // 【テストデータ準備】: 1回目、2回目、3回目のリトライ
    const baseDelay = 1000;

    // When（実行）: 各attemptで遅延時間を計算
    // 【実際の処理実行】: 指数バックオフアルゴリズムの計算
    const delay0 = calculateBackoffDelay(0, baseDelay);
    const delay1 = calculateBackoffDelay(1, baseDelay);
    const delay2 = calculateBackoffDelay(2, baseDelay);

    // Then（検証）: 各attemptで正しい遅延時間が計算される
    // 【結果検証】: baseDelay * (2 ^ attempt) の計算式
    expect(delay0).toBe(1000); // 1000 * (2 ^ 0) = 1000
    // 【確認内容】: attempt 0 → 1000ms
    expect(delay1).toBe(2000); // 1000 * (2 ^ 1) = 2000
    // 【確認内容】: attempt 1 → 2000ms
    expect(delay2).toBe(4000); // 1000 * (2 ^ 2) = 4000
    // 【確認内容】: attempt 2 → 4000ms
  });

  /**
   * TC-NORMAL-013: retryableRequest() - 成功パターン（1回目で成功）🔵
   *
   * 【テスト目的】: 1回目の実行が成功した場合にリトライなしで結果を返却すること
   * 【テスト内容】: 成功時はリトライしないことを検証
   * 【期待される動作】: 即座に結果を返却
   * 🔵 信頼性レベル: 青信号（要件定義書のretryableRequest()仕様から抽出）
   */
  it('TC-NORMAL-013: retryableRequest() - 成功パターン（1回目で成功）', async () => {
    // Given（前提条件）: 常に成功する関数を準備
    // 【テストデータ準備】: 正常に動作するAPI呼び出し
    const mockFn = vi.fn(async () => 'success result');
    const maxRetries = 3;

    // When（実行）: retryableRequest()を呼び出し
    // 【実際の処理実行】: 成功時はリトライしないこと
    const result = await retryableRequest(mockFn, maxRetries);

    // Then（検証）: 結果が返却される
    // 【結果検証】: 成功時は追加の試行不要
    expect(result).toBe('success result');
    // 【確認内容】: 正しい結果が返却される

    // Then: fnが1回だけ呼ばれる
    // 【結果検証】: 成功時は追加の試行不要
    expect(mockFn).toHaveBeenCalledTimes(1);
    // 【確認内容】: fnが1回だけ呼ばれること
  });
});

// =========================================
// 異常系テストケース（1件）
// =========================================
describe('retry.ts - 異常系テストケース', () => {
  beforeEach(() => {
    // 【テスト前準備】: 各テスト実行前にモックをクリア
    vi.clearAllMocks();
  });

  afterEach(() => {
    // 【テスト後処理】: タイマーモックをリセット
    vi.useRealTimers();
  });

  /**
   * TC-ERROR-007: retryableRequest() - 最大リトライ超過🔵
   *
   * 【テスト目的】: 最大リトライ回数に達したらエラーをスローすること
   * 【テスト内容】: すべてのリトライが失敗した場合の動作検証
   * 【期待される動作】: 最後のエラーがスローされる
   * 🔵 信頼性レベル: 青信号（要件定義書のretryableRequest()仕様から抽出）
   * 【エラーケースの概要】: すべてのリトライが失敗
   * 【エラー処理の重要性】: 無限リトライを防ぐ
   */
  it('TC-ERROR-007: retryableRequest() - 最大リトライ超過', async () => {
    // Given（前提条件）: 常に失敗する関数を準備
    // 【テストデータ準備】: API側の恒久的な障害
    // 【不正な理由】: API側の恒久的な障害
    // 【実際の発生シナリオ】: サービス停止、ネットワーク断絶
    const mockFn = vi.fn(async () => {
      throw new Error('Persistent error');
    });
    const maxRetries = 3;

    // When（実行）& Then（検証）: retryableRequest()を呼び出し、エラーがスローされることを検証
    // 【実際の処理実行】: すべてのリトライが失敗
    // 【結果検証】: 無限リトライによるリソース枯渇を防止
    await expect(retryableRequest(mockFn, maxRetries)).rejects.toThrow('Persistent error');
    // 【エラーメッセージの内容】: 最後のエラーがスローされる
    // 【システムの安全性】: フェイルファスト原則

    // Then: fnが3回呼ばれる
    // 【結果検証】: maxRetries回試行されること
    expect(mockFn).toHaveBeenCalledTimes(3);
    // 【確認内容】: fnが最大リトライ回数だけ呼ばれること
  });
});
